<?xml version="1.0" encoding="utf-8"?>
<!-- This URDF was automatically created by SolidWorks to URDF Exporter! Originally created by Stephen Brawner (brawner@gmail.com) 
     Commit Version: 1.6.0-1-g15f4949  Build Version: 1.6.7594.29634
     For more information, please see http://wiki.ros.org/sw_urdf_exporter -->
<robot
  name="ggul_bot_v7">
  <link
    name="base_link">
    <inertial>
      <origin
        xyz="-5.5389E-08 0.00093658 0.040581"
        rpy="0 0 0" />
      <mass
        value="0.99003" />
      <inertia
        ixx="0.0032068"
        ixy="8.4711E-09"
        ixz="-2.2548E-09"
        iyy="0.0032766"
        iyz="7.6826E-07"
        izz="0.0046336" />
    </inertial>
    <visual>
      <origin
        xyz="0 0 0"
        rpy="0 0 0" />
      <geometry>
        <mesh
          filename="package://ggul_bot_v7/meshes/base_link.STL" />
      </geometry>
      <material
        name="">
        <color
          rgba="1 1 1 1" />
      </material>
    </visual>
    <collision>
      <origin
        xyz="0 0 0"
        rpy="0 0 0" />
      <geometry>
        <mesh
          filename="package://ggul_bot_v7/meshes/base_link.STL" />
      </geometry>
    </collision>
  </link>
  <link
    name="arm_link1">
    <inertial>
      <origin
        xyz="2.1398E-05 0.018204 0.064666"
        rpy="0 0 0" />
      <mass
        value="0.52306" />
      <inertia
        ixx="0.0014942"
        ixy="1.0149E-07"
        ixz="-2.9691E-07"
        iyy="0.0016358"
        iyz="-0.00012699"
        izz="0.0013379" />
    </inertial>
    <visual>
      <origin
        xyz="0 0 0"
        rpy="0 0 0" />
      <geometry>
        <mesh
          filename="package://ggul_bot_v7/meshes/arm_link1.STL" />
      </geometry>
      <material
        name="">
        <color
          rgba="0.79216 0.81961 0.93333 1" />
      </material>
    </visual>
    <collision>
      <origin
        xyz="0 0 0"
        rpy="0 0 0" />
      <geometry>
        <mesh
          filename="package://ggul_bot_v7/meshes/arm_link1.STL" />
      </geometry>
    </collision>
  </link>
  <joint
    name="arm_joint1"
    type="revolute">
    <origin
      xyz="0 0.0003 0.1335"
      rpy="0 0 0" />
    <parent
      link="base_link" />
    <child
      link="arm_link1" />
    <axis
      xyz="0 0 1" />
    <limit
      lower="-3.1416"
      upper="3.1416"
      effort="0"
      velocity="0" />
  </joint>
  <link
    name="arm_link2">
    <inertial>
      <origin
        xyz="1.5185E-05 0.074972 0.15015"
        rpy="0 0 0" />
      <mass
        value="0.79074" />
      <inertia
        ixx="0.001998"
        ixy="8.8482E-08"
        ixz="6.1788E-08"
        iyy="0.0021552"
        iyz="-8.0631E-05"
        izz="0.0015782" />
    </inertial>
    <visual>
      <origin
        xyz="0 0 0"
        rpy="0 0 0" />
      <geometry>
        <mesh
          filename="package://ggul_bot_v7/meshes/arm_link2.STL" />
      </geometry>
      <material
        name="">
        <color
          rgba="1 1 1 1" />
      </material>
    </visual>
    <collision>
      <origin
        xyz="0 0 0"
        rpy="0 0 0" />
      <geometry>
        <mesh
          filename="package://ggul_bot_v7/meshes/arm_link2.STL" />
      </geometry>
    </collision>
  </link>
  <joint
    name="arm_joint2"
    type="revolute">
    <origin
      xyz="0 0.08563 0.0867"
      rpy="0 0 0" />
    <parent
      link="arm_link1" />
    <child
      link="arm_link2" />
    <axis
      xyz="0 1 0" />
    <limit
      lower="-1.5708"
      upper="1.5708"
      effort="0"
      velocity="0" />
  </joint>
  <link
    name="arm_link3">
    <inertial>
      <origin
        xyz="-5.3157E-06 -0.08046 0.15576"
        rpy="0 0 0" />
      <mass
        value="0.61887" />
      <inertia
        ixx="0.0012499"
        ixy="-3.3201E-08"
        ixz="-1.0129E-07"
        iyy="0.001164"
        iyz="1.2993E-05"
        izz="0.0011246" />
    </inertial>
    <visual>
      <origin
        xyz="0 0 0"
        rpy="0 0 0" />
      <geometry>
        <mesh
          filename="package://ggul_bot_v7/meshes/arm_link3.STL" />
      </geometry>
      <material
        name="">
        <color
          rgba="0.79216 0.81961 0.93333 1" />
      </material>
    </visual>
    <collision>
      <origin
        xyz="0 0 0"
        rpy="0 0 0" />
      <geometry>
        <mesh
          filename="package://ggul_bot_v7/meshes/arm_link3.STL" />
      </geometry>
    </collision>
  </link>
  <joint
    name="arm_joint3"
    type="revolute">
    <origin
      xyz="0 0.0155 0.31299"
      rpy="0 0 0" />
    <parent
      link="arm_link2" />
    <child
      link="arm_link3" />
    <axis
      xyz="0 1 0" />
    <limit
      lower="-2.4435"
      upper="2.4435"
      effort="0"
      velocity="0" />
  </joint>
  <link
    name="arm_link4">
    <inertial>
      <origin
        xyz="5.3547E-06 0.050417 0.018616"
        rpy="0 0 0" />
      <mass
        value="0.17483" />
      <inertia
        ixx="0.00036084"
        ixy="-3.3362E-08"
        ixz="-4.7116E-09"
        iyy="0.00035617"
        iyz="-7.5496E-05"
        izz="0.00025046" />
    </inertial>
    <visual>
      <origin
        xyz="0 0 0"
        rpy="0 0 0" />
      <geometry>
        <mesh
          filename="package://ggul_bot_v7/meshes/arm_link4.STL" />
      </geometry>
      <material
        name="">
        <color
          rgba="0.79216 0.81961 0.93333 1" />
      </material>
    </visual>
    <collision>
      <origin
        xyz="0 0 0"
        rpy="0 0 0" />
      <geometry>
        <mesh
          filename="package://ggul_bot_v7/meshes/arm_link4.STL" />
      </geometry>
    </collision>
  </link>
  <joint
    name="arm_joint4"
    type="revolute">
    <origin
      xyz="0 -0.0285 0.265"
      rpy="0 0 0" />
    <parent
      link="arm_link3" />
    <child
      link="arm_link4" />
    <axis
      xyz="0 -1 0" />
    <limit
      lower="-2.4435"
      upper="2.4435"
      effort="0"
      velocity="0" />
  </joint>
  <link
    name="arm_link5">
    <inertial>
      <origin
        xyz="-2.1132E-05 -0.029061 0.083196"
        rpy="0 0 0" />
      <mass
        value="0.21405" />
      <inertia
        ixx="0.00052885"
        ixy="1.1518E-07"
        ixz="7.4918E-08"
        iyy="0.00037379"
        iyz="0.00010996"
        izz="0.00042184" />
    </inertial>
    <visual>
      <origin
        xyz="0 0 0"
        rpy="0 0 0" />
      <geometry>
        <mesh
          filename="package://ggul_bot_v7/meshes/arm_link5.STL" />
      </geometry>
      <material
        name="">
        <color
          rgba="0.79216 0.81961 0.93333 1" />
      </material>
    </visual>
    <collision>
      <origin
        xyz="0 0 0"
        rpy="0 0 0" />
      <geometry>
        <mesh
          filename="package://ggul_bot_v7/meshes/arm_link5.STL" />
      </geometry>
    </collision>
  </link>
  <joint
    name="arm_joint5"
    type="revolute">
    <origin
      xyz="0 0.06699 0.09551"
      rpy="0 0 0" />
    <parent
      link="arm_link4" />
    <child
      link="arm_link5" />
    <axis
      xyz="0 0 1" />
    <limit
      lower="-3.1416"
      upper="3.1416"
      effort="0"
      velocity="0" />
  </joint>
  <link
    name="end_eff_link">
    <inertial>
      <origin
        xyz="-9.7645E-18 -0.0098994 -3.189E-05"
        rpy="0 0 0" />
      <mass
        value="0.038629" />
      <inertia
        ixx="1.5427E-05"
        ixy="1.2167E-19"
        ixz="-2.6205E-20"
        iyy="2.968E-05"
        iyz="6.9593E-09"
        izz="1.5472E-05" />
    </inertial>
    <visual>
      <origin
        xyz="0 0 0"
        rpy="0 0 0" />
      <geometry>
        <mesh
          filename="package://ggul_bot_v7/meshes/end_eff_link.STL" />
      </geometry>
      <material
        name="">
        <color
          rgba="1 1 1 1" />
      </material>
    </visual>
    <collision>
      <origin
        xyz="0 0 0"
        rpy="0 0 0" />
      <geometry>
        <mesh
          filename="package://ggul_bot_v7/meshes/end_eff_link.STL" />
      </geometry>
    </collision>
  </link>
  <joint
    name="end_eff_joint"
    type="revolute">
    <origin
      xyz="0 -0.10849 0.0955"
      rpy="0 0 0" />
    <parent
      link="arm_link5" />
    <child
      link="end_eff_link" />
    <axis
      xyz="0 1 0" />
    <limit
      lower="-3.1416"
      upper="3.1416"
      effort="0"
      velocity="0" />
  </joint>
</robot>